<?xml version="1.0" encoding="UTF-8"?>
<!-- Generated by org.testng.reporters.JUnitXMLReporter -->
<testsuite hostname="PDWIVEDI" name="ETL Test" tests="10" failures="10" timestamp="28 May 2014 13:44:00 GMT" time="28.146" errors="0">
  <testcase name="demoCASE_ID" time="0.292" classname="com.sapphire.etl.AERSDemoVerify">
    <failure type="java.lang.AssertionError" message="SELECT coun(*) FROM aers_demo where case_id is null">
      <![CDATA[java.lang.AssertionError: SELECT coun(*) FROM aers_demo where case_id is null
	at com.sapphire.etl.AERSDemoVerify.demoCASE_ID(AERSDemoVerify.java:141)
Caused by: com.mysql.jdbc.exceptions.jdbc4.MySQLSyntaxErrorException: You have an error in your SQL syntax; check the manual that corresponds to your MySQL server version for the right syntax to use near '*) FROM aers_demo where case_id is null' at line 1
	at com.mysql.jdbc.Util.handleNewInstance(Util.java:411)
	at com.mysql.jdbc.Util.getInstance(Util.java:386)
	at com.mysql.jdbc.SQLError.createSQLException(SQLError.java:1052)
	at com.mysql.jdbc.MysqlIO.checkErrorPacket(MysqlIO.java:3609)
	at com.mysql.jdbc.MysqlIO.checkErrorPacket(MysqlIO.java:3541)
	at com.mysql.jdbc.MysqlIO.sendCommand(MysqlIO.java:2002)
	at com.mysql.jdbc.MysqlIO.sqlQueryDirect(MysqlIO.java:2163)
	at com.mysql.jdbc.ConnectionImpl.execSQL(ConnectionImpl.java:2618)
	at com.mysql.jdbc.ConnectionImpl.execSQL(ConnectionImpl.java:2568)
	at com.mysql.jdbc.StatementImpl.executeQuery(StatementImpl.java:1557)
	at com.sapphire.etl.AERSDemoVerify.demoCASE_ID(AERSDemoVerify.java:128)
	... 24 more
... Removed 29 stack frames]]>
    </failure>
  </testcase> <!-- demoCASE_ID -->
  <testcase name="demoCaseAgeCode" time="8.149" classname="com.sapphire.etl.AERSDemoVerify">
    <failure type="java.lang.AssertionError" message="SELECT distinct age_code FROM aers_demo">
      <![CDATA[java.lang.AssertionError: SELECT distinct age_code FROM aers_demo
	at com.sapphire.etl.AERSDemoVerify.demoCaseAgeCode(AERSDemoVerify.java:314)
Caused by: java.lang.AssertionError: null: lists don't have the same size expected [9] but found [13]
	at com.sapphire.etl.AERSDemoVerify.demoCaseAgeCode(AERSDemoVerify.java:309)
	... 24 more
... Removed 31 stack frames]]>
    </failure>
  </testcase> <!-- demoCaseAgeCode -->
  <testcase name="demoCaseAgeGroup" time="4.433" classname="com.sapphire.etl.AERSDemoVerify">
    <failure type="java.lang.AssertionError" message="SELECT count(*) FROM aers_demo where std_age_group = &amp;apos;Not Available&amp;apos; AND age != &amp;apos;&amp;apos; AND age_code != &amp;apos;&amp;apos; AND age not like (&amp;apos;%-%&amp;apos;) AND age not like (&amp;apos;%.%&amp;apos;) AND age != 0 AND age != 00">
      <![CDATA[java.lang.AssertionError: SELECT count(*) FROM aers_demo where std_age_group = 'Not Available' AND age != '' AND age_code != '' AND age not like ('%-%') AND age not like ('%.%') AND age != 0 AND age != 00
	at com.sapphire.etl.AERSDemoVerify.demoCaseAgeGroup(AERSDemoVerify.java:351)
Caused by: java.sql.SQLException: Column Index out of range, 2 > 1. 
	at com.mysql.jdbc.SQLError.createSQLException(SQLError.java:1073)
	at com.mysql.jdbc.SQLError.createSQLException(SQLError.java:987)
	at com.mysql.jdbc.SQLError.createSQLException(SQLError.java:982)
	at com.mysql.jdbc.SQLError.createSQLException(SQLError.java:927)
	at com.mysql.jdbc.ResultSetImpl.checkColumnBounds(ResultSetImpl.java:818)
	at com.mysql.jdbc.ResultSetImpl.getStringInternal(ResultSetImpl.java:5651)
	at com.mysql.jdbc.ResultSetImpl.getString(ResultSetImpl.java:5570)
	at com.sapphire.etl.AERSDemoVerify.demoCaseAgeGroup(AERSDemoVerify.java:340)
	... 24 more
... Removed 25 stack frames]]>
    </failure>
  </testcase> <!-- demoCaseAgeGroup -->
  <testcase name="demoCaseGenderCode" time="8.12" classname="com.sapphire.etl.AERSDemoVerify">
    <failure type="java.lang.AssertionError" message="SELECT distinct gender_code FROM aers_demo">
      <![CDATA[java.lang.AssertionError: SELECT distinct gender_code FROM aers_demo
	at com.sapphire.etl.AERSDemoVerify.demoCaseGenderCode(AERSDemoVerify.java:207)
Caused by: java.lang.AssertionError: null: lists don't have the same size expected [6] but found [10]
	at com.sapphire.etl.AERSDemoVerify.demoCaseGenderCode(AERSDemoVerify.java:202)
	... 24 more
... Removed 31 stack frames]]>
    </failure>
  </testcase> <!-- demoCaseGenderCode -->
  <testcase name="demoCaseGenderDEC" time="0.026" classname="com.sapphire.etl.AERSDemoVerify">
    <failure type="java.lang.AssertionError" message="SELECT distinct gender_dec FROM aers_demo">
      <![CDATA[java.lang.AssertionError: SELECT distinct gender_dec FROM aers_demo
	at com.sapphire.etl.AERSDemoVerify.demoCaseGenderDEC(AERSDemoVerify.java:242)
Caused by: java.sql.SQLException: Column Index out of range, 2 > 1. 
	at com.mysql.jdbc.SQLError.createSQLException(SQLError.java:1073)
	at com.mysql.jdbc.SQLError.createSQLException(SQLError.java:987)
	at com.mysql.jdbc.SQLError.createSQLException(SQLError.java:982)
	at com.mysql.jdbc.SQLError.createSQLException(SQLError.java:927)
	at com.mysql.jdbc.ResultSetImpl.checkColumnBounds(ResultSetImpl.java:818)
	at com.mysql.jdbc.ResultSetImpl.getStringInternal(ResultSetImpl.java:5651)
	at com.mysql.jdbc.ResultSetImpl.getString(ResultSetImpl.java:5570)
	at com.sapphire.etl.AERSDemoVerify.demoCaseGenderDEC(AERSDemoVerify.java:228)
	... 24 more
... Removed 25 stack frames]]>
    </failure>
  </testcase> <!-- demoCaseGenderDEC -->
  <testcase name="demoCaseSeriousness" time="6.996" classname="com.sapphire.etl.AERSDemoVerify">
    <failure type="java.lang.AssertionError" message="SELECT count(*) FROM aers_demo where seriousness = 1 and ( outc_death= 0 and  outc_life_threat =0 and outc_hosp =0 and outc_disability=0 and outc_cong_anomaly=0  and outc_reqd_interv=0 and outc_other=0 and outc_none=0 and outc_rec=0 and outc_rx=0)">
      <![CDATA[java.lang.AssertionError: SELECT count(*) FROM aers_demo where seriousness = 1 and ( outc_death= 0 and  outc_life_threat =0 and outc_hosp =0 and outc_disability=0 and outc_cong_anomaly=0  and outc_reqd_interv=0 and outc_other=0 and outc_none=0 and outc_rec=0 and outc_rx=0)
	at com.sapphire.etl.AERSDemoVerify.demoCaseSeriousness(AERSDemoVerify.java:275)
Caused by: java.sql.SQLException: Column Index out of range, 12 > 1. 
	at com.mysql.jdbc.SQLError.createSQLException(SQLError.java:1073)
	at com.mysql.jdbc.SQLError.createSQLException(SQLError.java:987)
	at com.mysql.jdbc.SQLError.createSQLException(SQLError.java:982)
	at com.mysql.jdbc.SQLError.createSQLException(SQLError.java:927)
	at com.mysql.jdbc.ResultSetImpl.checkColumnBounds(ResultSetImpl.java:818)
	at com.mysql.jdbc.ResultSetImpl.getStringInternal(ResultSetImpl.java:5651)
	at com.mysql.jdbc.ResultSetImpl.getString(ResultSetImpl.java:5570)
	at com.sapphire.etl.AERSDemoVerify.demoCaseSeriousness(AERSDemoVerify.java:265)
	... 24 more
... Removed 25 stack frames]]>
    </failure>
  </testcase> <!-- demoCaseSeriousness -->
  <testcase name="demoCaseValidFrom" time="0.031" classname="com.sapphire.etl.AERSDemoVerify">
    <failure type="java.lang.AssertionError" message="SELECT count(*) FROM aers_demo where valid_from is null">
      <![CDATA[java.lang.AssertionError: SELECT count(*) FROM aers_demo where valid_from is null
	at com.sapphire.etl.AERSDemoVerify.demoCaseValidFrom(AERSDemoVerify.java:44)
Caused by: java.lang.AssertionError: null: lists don't have the same size expected [0] but found [1]
	at com.sapphire.etl.AERSDemoVerify.demoCaseValidFrom(AERSDemoVerify.java:39)
	... 24 more
... Removed 31 stack frames]]>
    </failure>
  </testcase> <!-- demoCaseValidFrom -->
  <testcase name="demoCaseValidTo" time="0.028" classname="com.sapphire.etl.AERSDemoVerify">
    <failure type="java.lang.AssertionError" message="SELECT count(*) FROM aers_demo where valid_to is null">
      <![CDATA[java.lang.AssertionError: SELECT count(*) FROM aers_demo where valid_to is null
	at com.sapphire.etl.AERSDemoVerify.demoCaseValidTo(AERSDemoVerify.java:76)
Caused by: java.lang.AssertionError: null: lists don't have the same size expected [0] but found [1]
	at com.sapphire.etl.AERSDemoVerify.demoCaseValidTo(AERSDemoVerify.java:71)
	... 24 more
... Removed 31 stack frames]]>
    </failure>
  </testcase> <!-- demoCaseValidTo -->
  <testcase name="demoFDA_date" time="0.023" classname="com.sapphire.etl.AERSDemoVerify">
    <failure type="java.lang.AssertionError" message="SELECT count(*) FROM aers_demo where fda_date is null">
      <![CDATA[java.lang.AssertionError: SELECT count(*) FROM aers_demo where fda_date is null
	at com.sapphire.etl.AERSDemoVerify.demoFDA_date(AERSDemoVerify.java:171)
Caused by: java.lang.AssertionError: null: lists don't have the same size expected [0] but found [1]
	at com.sapphire.etl.AERSDemoVerify.demoFDA_date(AERSDemoVerify.java:166)
	... 24 more
... Removed 31 stack frames]]>
    </failure>
  </testcase> <!-- demoFDA_date -->
  <testcase name="demoISR_ID" time="0.026" classname="com.sapphire.etl.AERSDemoVerify">
    <failure type="java.lang.AssertionError" message="SELECT count(*) FROM aers_demo where isr_id is null">
      <![CDATA[java.lang.AssertionError: SELECT count(*) FROM aers_demo where isr_id is null
	at com.sapphire.etl.AERSDemoVerify.demoISR_ID(AERSDemoVerify.java:109)
Caused by: java.lang.AssertionError: null: lists don't have the same size expected [0] but found [1]
	at com.sapphire.etl.AERSDemoVerify.demoISR_ID(AERSDemoVerify.java:104)
	... 24 more
... Removed 31 stack frames]]>
    </failure>
  </testcase> <!-- demoISR_ID -->
</testsuite> <!-- ETL Test -->
