<?xml version="1.0" encoding="UTF-8"?>
<!-- Generated by org.testng.reporters.JUnitXMLReporter -->
<testsuite hostname="PDWIVEDI" name="Default test" tests="10" failures="5" timestamp="30 May 2014 06:49:32 GMT" time="5.263" errors="0">
  <testcase name="demoCASE_ID" time="0.632" classname="com.sapphire.etl.AERSDemoVerify"/>
  <testcase name="demoCaseAgeCode" time="0.036" classname="com.sapphire.etl.AERSDemoVerify">
    <failure type="java.lang.AssertionError" message="SELECT distinct age_code FROM aers_demo">
      <![CDATA[java.lang.AssertionError: SELECT distinct age_code FROM aers_demo
	at org.testng.Assert.fail(Assert.java:83)
	at com.sapphire.etl.AERSDemoVerify.demoCaseAgeCode(AERSDemoVerify.java:352)
	at sun.reflect.NativeMethodAccessorImpl.invoke0(Native Method)
	at sun.reflect.NativeMethodAccessorImpl.invoke(NativeMethodAccessorImpl.java:39)
	at sun.reflect.DelegatingMethodAccessorImpl.invoke(DelegatingMethodAccessorImpl.java:25)
	at java.lang.reflect.Method.invoke(Method.java:597)
	at org.testng.internal.MethodInvocationHelper.invokeMethod(MethodInvocationHelper.java:84)
	at org.testng.internal.Invoker.invokeMethod(Invoker.java:714)
	at org.testng.internal.Invoker.invokeTestMethod(Invoker.java:901)
	at org.testng.internal.Invoker.invokeTestMethods(Invoker.java:1231)
	at org.testng.internal.TestMethodWorker.invokeTestMethods(TestMethodWorker.java:127)
	at org.testng.internal.TestMethodWorker.run(TestMethodWorker.java:111)
	at org.testng.TestRunner.privateRun(TestRunner.java:767)
	at org.testng.TestRunner.run(TestRunner.java:617)
	at org.testng.SuiteRunner.runTest(SuiteRunner.java:334)
	at org.testng.SuiteRunner.runSequentially(SuiteRunner.java:329)
	at org.testng.SuiteRunner.privateRun(SuiteRunner.java:291)
	at org.testng.SuiteRunner.run(SuiteRunner.java:240)
	at org.testng.SuiteRunnerWorker.runSuite(SuiteRunnerWorker.java:52)
	at org.testng.SuiteRunnerWorker.run(SuiteRunnerWorker.java:86)
	at org.testng.TestNG.runSuitesSequentially(TestNG.java:1224)
	at org.testng.TestNG.runSuitesLocally(TestNG.java:1149)
	at org.testng.TestNG.run(TestNG.java:1057)
	at org.testng.remote.RemoteTestNG.run(RemoteTestNG.java:111)
	at org.testng.remote.RemoteTestNG.initAndRun(RemoteTestNG.java:204)
	at org.testng.remote.RemoteTestNG.main(RemoteTestNG.java:175)
Caused by: java.lang.AssertionError: null: lists don't have the same size expected [9] but found [13]
	at org.testng.Assert.fail(Assert.java:94)
	at org.testng.Assert.failNotEquals(Assert.java:494)
	at org.testng.Assert.assertEquals(Assert.java:123)
	at org.testng.Assert.assertEquals(Assert.java:370)
	at org.testng.Assert.assertEquals(Assert.java:537)
	at org.testng.Assert.assertEquals(Assert.java:514)
	at com.sapphire.etl.AERSDemoVerify.demoCaseAgeCode(AERSDemoVerify.java:345)
	... 24 more
]]>
    </failure>
  </testcase> <!-- demoCaseAgeCode -->
  <testcase name="demoCaseAgeGroup" time="4.345" classname="com.sapphire.etl.AERSDemoVerify">
    <failure type="java.lang.AssertionError" message="SELECT count(*) FROM aers_demo where std_age_group = &amp;apos;Not Available&amp;apos; AND age != &amp;apos;&amp;apos; AND age_code != &amp;apos;&amp;apos; AND age not like (&amp;apos;%-%&amp;apos;) AND age not like (&amp;apos;%.%&amp;apos;) AND age != 0 AND age != 00">
      <![CDATA[java.lang.AssertionError: SELECT count(*) FROM aers_demo where std_age_group = 'Not Available' AND age != '' AND age_code != '' AND age not like ('%-%') AND age not like ('%.%') AND age != 0 AND age != 00
	at org.testng.Assert.fail(Assert.java:83)
	at com.sapphire.etl.AERSDemoVerify.demoCaseAgeGroup(AERSDemoVerify.java:389)
	at sun.reflect.NativeMethodAccessorImpl.invoke0(Native Method)
	at sun.reflect.NativeMethodAccessorImpl.invoke(NativeMethodAccessorImpl.java:39)
	at sun.reflect.DelegatingMethodAccessorImpl.invoke(DelegatingMethodAccessorImpl.java:25)
	at java.lang.reflect.Method.invoke(Method.java:597)
	at org.testng.internal.MethodInvocationHelper.invokeMethod(MethodInvocationHelper.java:84)
	at org.testng.internal.Invoker.invokeMethod(Invoker.java:714)
	at org.testng.internal.Invoker.invokeTestMethod(Invoker.java:901)
	at org.testng.internal.Invoker.invokeTestMethods(Invoker.java:1231)
	at org.testng.internal.TestMethodWorker.invokeTestMethods(TestMethodWorker.java:127)
	at org.testng.internal.TestMethodWorker.run(TestMethodWorker.java:111)
	at org.testng.TestRunner.privateRun(TestRunner.java:767)
	at org.testng.TestRunner.run(TestRunner.java:617)
	at org.testng.SuiteRunner.runTest(SuiteRunner.java:334)
	at org.testng.SuiteRunner.runSequentially(SuiteRunner.java:329)
	at org.testng.SuiteRunner.privateRun(SuiteRunner.java:291)
	at org.testng.SuiteRunner.run(SuiteRunner.java:240)
	at org.testng.SuiteRunnerWorker.runSuite(SuiteRunnerWorker.java:52)
	at org.testng.SuiteRunnerWorker.run(SuiteRunnerWorker.java:86)
	at org.testng.TestNG.runSuitesSequentially(TestNG.java:1224)
	at org.testng.TestNG.runSuitesLocally(TestNG.java:1149)
	at org.testng.TestNG.run(TestNG.java:1057)
	at org.testng.remote.RemoteTestNG.run(RemoteTestNG.java:111)
	at org.testng.remote.RemoteTestNG.initAndRun(RemoteTestNG.java:204)
	at org.testng.remote.RemoteTestNG.main(RemoteTestNG.java:175)
Caused by: java.lang.AssertionError: Lists differ at element [0]: 0 != 631 expected [0] but found [631]
	at org.testng.Assert.fail(Assert.java:94)
	at org.testng.Assert.failNotEquals(Assert.java:494)
	at org.testng.Assert.assertEquals(Assert.java:123)
	at org.testng.Assert.assertEquals(Assert.java:549)
	at org.testng.Assert.assertEquals(Assert.java:514)
	at com.sapphire.etl.AERSDemoVerify.demoCaseAgeGroup(AERSDemoVerify.java:382)
	... 24 more
]]>
    </failure>
  </testcase> <!-- demoCaseAgeGroup -->
  <testcase name="demoCaseGenderCode" time="0.036" classname="com.sapphire.etl.AERSDemoVerify">
    <failure type="java.lang.AssertionError" message="SELECT distinct gender_code FROM aers_demo">
      <![CDATA[java.lang.AssertionError: SELECT distinct gender_code FROM aers_demo
	at org.testng.Assert.fail(Assert.java:83)
	at com.sapphire.etl.AERSDemoVerify.demoCaseGenderCode(AERSDemoVerify.java:234)
	at sun.reflect.NativeMethodAccessorImpl.invoke0(Native Method)
	at sun.reflect.NativeMethodAccessorImpl.invoke(NativeMethodAccessorImpl.java:39)
	at sun.reflect.DelegatingMethodAccessorImpl.invoke(DelegatingMethodAccessorImpl.java:25)
	at java.lang.reflect.Method.invoke(Method.java:597)
	at org.testng.internal.MethodInvocationHelper.invokeMethod(MethodInvocationHelper.java:84)
	at org.testng.internal.Invoker.invokeMethod(Invoker.java:714)
	at org.testng.internal.Invoker.invokeTestMethod(Invoker.java:901)
	at org.testng.internal.Invoker.invokeTestMethods(Invoker.java:1231)
	at org.testng.internal.TestMethodWorker.invokeTestMethods(TestMethodWorker.java:127)
	at org.testng.internal.TestMethodWorker.run(TestMethodWorker.java:111)
	at org.testng.TestRunner.privateRun(TestRunner.java:767)
	at org.testng.TestRunner.run(TestRunner.java:617)
	at org.testng.SuiteRunner.runTest(SuiteRunner.java:334)
	at org.testng.SuiteRunner.runSequentially(SuiteRunner.java:329)
	at org.testng.SuiteRunner.privateRun(SuiteRunner.java:291)
	at org.testng.SuiteRunner.run(SuiteRunner.java:240)
	at org.testng.SuiteRunnerWorker.runSuite(SuiteRunnerWorker.java:52)
	at org.testng.SuiteRunnerWorker.run(SuiteRunnerWorker.java:86)
	at org.testng.TestNG.runSuitesSequentially(TestNG.java:1224)
	at org.testng.TestNG.runSuitesLocally(TestNG.java:1149)
	at org.testng.TestNG.run(TestNG.java:1057)
	at org.testng.remote.RemoteTestNG.run(RemoteTestNG.java:111)
	at org.testng.remote.RemoteTestNG.initAndRun(RemoteTestNG.java:204)
	at org.testng.remote.RemoteTestNG.main(RemoteTestNG.java:175)
Caused by: java.lang.AssertionError: null: lists don't have the same size expected [6] but found [10]
	at org.testng.Assert.fail(Assert.java:94)
	at org.testng.Assert.failNotEquals(Assert.java:494)
	at org.testng.Assert.assertEquals(Assert.java:123)
	at org.testng.Assert.assertEquals(Assert.java:370)
	at org.testng.Assert.assertEquals(Assert.java:537)
	at org.testng.Assert.assertEquals(Assert.java:514)
	at com.sapphire.etl.AERSDemoVerify.demoCaseGenderCode(AERSDemoVerify.java:227)
	... 24 more
]]>
    </failure>
  </testcase> <!-- demoCaseGenderCode -->
  <testcase name="demoCaseGenderDEC" time="0.041" classname="com.sapphire.etl.AERSDemoVerify">
    <failure type="java.lang.AssertionError" message="SELECT distinct gender_dec FROM aers_demo">
      <![CDATA[java.lang.AssertionError: SELECT distinct gender_dec FROM aers_demo
	at org.testng.Assert.fail(Assert.java:83)
	at com.sapphire.etl.AERSDemoVerify.demoCaseGenderDEC(AERSDemoVerify.java:273)
	at sun.reflect.NativeMethodAccessorImpl.invoke0(Native Method)
	at sun.reflect.NativeMethodAccessorImpl.invoke(NativeMethodAccessorImpl.java:39)
	at sun.reflect.DelegatingMethodAccessorImpl.invoke(DelegatingMethodAccessorImpl.java:25)
	at java.lang.reflect.Method.invoke(Method.java:597)
	at org.testng.internal.MethodInvocationHelper.invokeMethod(MethodInvocationHelper.java:84)
	at org.testng.internal.Invoker.invokeMethod(Invoker.java:714)
	at org.testng.internal.Invoker.invokeTestMethod(Invoker.java:901)
	at org.testng.internal.Invoker.invokeTestMethods(Invoker.java:1231)
	at org.testng.internal.TestMethodWorker.invokeTestMethods(TestMethodWorker.java:127)
	at org.testng.internal.TestMethodWorker.run(TestMethodWorker.java:111)
	at org.testng.TestRunner.privateRun(TestRunner.java:767)
	at org.testng.TestRunner.run(TestRunner.java:617)
	at org.testng.SuiteRunner.runTest(SuiteRunner.java:334)
	at org.testng.SuiteRunner.runSequentially(SuiteRunner.java:329)
	at org.testng.SuiteRunner.privateRun(SuiteRunner.java:291)
	at org.testng.SuiteRunner.run(SuiteRunner.java:240)
	at org.testng.SuiteRunnerWorker.runSuite(SuiteRunnerWorker.java:52)
	at org.testng.SuiteRunnerWorker.run(SuiteRunnerWorker.java:86)
	at org.testng.TestNG.runSuitesSequentially(TestNG.java:1224)
	at org.testng.TestNG.runSuitesLocally(TestNG.java:1149)
	at org.testng.TestNG.run(TestNG.java:1057)
	at org.testng.remote.RemoteTestNG.run(RemoteTestNG.java:111)
	at org.testng.remote.RemoteTestNG.initAndRun(RemoteTestNG.java:204)
	at org.testng.remote.RemoteTestNG.main(RemoteTestNG.java:175)
Caused by: java.sql.SQLException: Column Index out of range, 2 > 1. 
	at com.mysql.jdbc.SQLError.createSQLException(SQLError.java:1073)
	at com.mysql.jdbc.SQLError.createSQLException(SQLError.java:987)
	at com.mysql.jdbc.SQLError.createSQLException(SQLError.java:982)
	at com.mysql.jdbc.SQLError.createSQLException(SQLError.java:927)
	at com.mysql.jdbc.ResultSetImpl.checkColumnBounds(ResultSetImpl.java:818)
	at com.mysql.jdbc.ResultSetImpl.getStringInternal(ResultSetImpl.java:5651)
	at com.mysql.jdbc.ResultSetImpl.getString(ResultSetImpl.java:5570)
	at com.sapphire.etl.AERSDemoVerify.demoCaseGenderDEC(AERSDemoVerify.java:257)
	... 24 more
]]>
    </failure>
  </testcase> <!-- demoCaseGenderDEC -->
  <testcase name="demoCaseSeriousness" time="0.029" classname="com.sapphire.etl.AERSDemoVerify"/>
  <testcase name="demoCaseValidFrom" time="0.036" classname="com.sapphire.etl.AERSDemoVerify"/>
  <testcase name="demoCaseValidTo" time="0.033" classname="com.sapphire.etl.AERSDemoVerify">
    <failure type="java.lang.AssertionError" message="SELECT count(*) FROM aers_demo where valid_to is null">
      <![CDATA[java.lang.AssertionError: SELECT count(*) FROM aers_demo where valid_to is null
	at org.testng.Assert.fail(Assert.java:83)
	at com.sapphire.etl.AERSDemoVerify.demoCaseValidTo(AERSDemoVerify.java:83)
	at sun.reflect.NativeMethodAccessorImpl.invoke0(Native Method)
	at sun.reflect.NativeMethodAccessorImpl.invoke(NativeMethodAccessorImpl.java:39)
	at sun.reflect.DelegatingMethodAccessorImpl.invoke(DelegatingMethodAccessorImpl.java:25)
	at java.lang.reflect.Method.invoke(Method.java:597)
	at org.testng.internal.MethodInvocationHelper.invokeMethod(MethodInvocationHelper.java:84)
	at org.testng.internal.Invoker.invokeMethod(Invoker.java:714)
	at org.testng.internal.Invoker.invokeTestMethod(Invoker.java:901)
	at org.testng.internal.Invoker.invokeTestMethods(Invoker.java:1231)
	at org.testng.internal.TestMethodWorker.invokeTestMethods(TestMethodWorker.java:127)
	at org.testng.internal.TestMethodWorker.run(TestMethodWorker.java:111)
	at org.testng.TestRunner.privateRun(TestRunner.java:767)
	at org.testng.TestRunner.run(TestRunner.java:617)
	at org.testng.SuiteRunner.runTest(SuiteRunner.java:334)
	at org.testng.SuiteRunner.runSequentially(SuiteRunner.java:329)
	at org.testng.SuiteRunner.privateRun(SuiteRunner.java:291)
	at org.testng.SuiteRunner.run(SuiteRunner.java:240)
	at org.testng.SuiteRunnerWorker.runSuite(SuiteRunnerWorker.java:52)
	at org.testng.SuiteRunnerWorker.run(SuiteRunnerWorker.java:86)
	at org.testng.TestNG.runSuitesSequentially(TestNG.java:1224)
	at org.testng.TestNG.runSuitesLocally(TestNG.java:1149)
	at org.testng.TestNG.run(TestNG.java:1057)
	at org.testng.remote.RemoteTestNG.run(RemoteTestNG.java:111)
	at org.testng.remote.RemoteTestNG.initAndRun(RemoteTestNG.java:204)
	at org.testng.remote.RemoteTestNG.main(RemoteTestNG.java:175)
Caused by: java.lang.AssertionError: Lists differ at element [0]: 0 != 13 expected [0] but found [13]
	at org.testng.Assert.fail(Assert.java:94)
	at org.testng.Assert.failNotEquals(Assert.java:494)
	at org.testng.Assert.assertEquals(Assert.java:123)
	at org.testng.Assert.assertEquals(Assert.java:549)
	at org.testng.Assert.assertEquals(Assert.java:514)
	at com.sapphire.etl.AERSDemoVerify.demoCaseValidTo(AERSDemoVerify.java:76)
	... 24 more
]]>
    </failure>
  </testcase> <!-- demoCaseValidTo -->
  <testcase name="demoFDA_date" time="0.028" classname="com.sapphire.etl.AERSDemoVerify"/>
  <testcase name="demoISR_ID" time="0.028" classname="com.sapphire.etl.AERSDemoVerify"/>
</testsuite> <!-- Default test -->
