<?xml version="1.0" encoding="UTF-8"?>
<!-- Generated by org.testng.reporters.JUnitReportReporter -->
<testsuite hostname="PDWIVEDI" name="com.sapphire.etl.Demo" tests="9" failures="0" timestamp="26 May 2014 11:31:52 GMT" time="42.012" errors="3">
  <testcase name="demoFDA_dateCaseCount" time="0.022" classname="com.sapphire.etl.Demo"/>
  <testcase name="demoFDA_date" time="0.040" classname="com.sapphire.etl.Demo"/>
  <testcase name="demoCaseGenderCode" time="0.033" classname="com.sapphire.etl.Demo">
    <error type="java.lang.AssertionError" message="ERROR">
      <![CDATA[java.lang.AssertionError: ERROR
	at org.testng.Assert.fail(Assert.java:83)
	at com.sapphire.etl.Demo.demoCaseGenderCode(Demo.java:264)
	at sun.reflect.NativeMethodAccessorImpl.invoke0(Native Method)
	at sun.reflect.NativeMethodAccessorImpl.invoke(NativeMethodAccessorImpl.java:39)
	at sun.reflect.DelegatingMethodAccessorImpl.invoke(DelegatingMethodAccessorImpl.java:25)
	at java.lang.reflect.Method.invoke(Method.java:597)
	at org.testng.internal.MethodInvocationHelper.invokeMethod(MethodInvocationHelper.java:84)
	at org.testng.internal.Invoker.invokeMethod(Invoker.java:714)
	at org.testng.internal.Invoker.invokeTestMethod(Invoker.java:901)
	at org.testng.internal.Invoker.invokeTestMethods(Invoker.java:1231)
	at org.testng.internal.TestMethodWorker.invokeTestMethods(TestMethodWorker.java:127)
	at org.testng.internal.TestMethodWorker.run(TestMethodWorker.java:111)
	at org.testng.TestRunner.privateRun(TestRunner.java:767)
	at org.testng.TestRunner.run(TestRunner.java:617)
	at org.testng.SuiteRunner.runTest(SuiteRunner.java:334)
	at org.testng.SuiteRunner.runSequentially(SuiteRunner.java:329)
	at org.testng.SuiteRunner.privateRun(SuiteRunner.java:291)
	at org.testng.SuiteRunner.run(SuiteRunner.java:240)
	at org.testng.SuiteRunnerWorker.runSuite(SuiteRunnerWorker.java:52)
	at org.testng.SuiteRunnerWorker.run(SuiteRunnerWorker.java:86)
	at org.testng.TestNG.runSuitesSequentially(TestNG.java:1224)
	at org.testng.TestNG.runSuitesLocally(TestNG.java:1149)
	at org.testng.TestNG.run(TestNG.java:1057)
	at org.testng.remote.RemoteTestNG.run(RemoteTestNG.java:111)
	at org.testng.remote.RemoteTestNG.initAndRun(RemoteTestNG.java:204)
	at org.testng.remote.RemoteTestNG.main(RemoteTestNG.java:175)
Caused by: java.lang.AssertionError: List Matching...............: lists don't have the same size expected [5] but found [10]
	at org.testng.Assert.fail(Assert.java:94)
	at org.testng.Assert.failNotEquals(Assert.java:494)
	at org.testng.Assert.assertEquals(Assert.java:123)
	at org.testng.Assert.assertEquals(Assert.java:370)
	at org.testng.Assert.assertEquals(Assert.java:537)
	at com.sapphire.etl.Demo.demoCaseGenderCode(Demo.java:259)
	... 24 more
]]>
    </error>
  </testcase> <!-- demoCaseGenderCode -->
  <testcase name="demoCaseSeriousness" time="41.567" classname="com.sapphire.etl.Demo">
    <error type="java.lang.AssertionError" message="ERROR">
      <![CDATA[java.lang.AssertionError: ERROR
	at org.testng.Assert.fail(Assert.java:83)
	at com.sapphire.etl.Demo.demoCaseSeriousness(Demo.java:345)
	at sun.reflect.NativeMethodAccessorImpl.invoke0(Native Method)
	at sun.reflect.NativeMethodAccessorImpl.invoke(NativeMethodAccessorImpl.java:39)
	at sun.reflect.DelegatingMethodAccessorImpl.invoke(DelegatingMethodAccessorImpl.java:25)
	at java.lang.reflect.Method.invoke(Method.java:597)
	at org.testng.internal.MethodInvocationHelper.invokeMethod(MethodInvocationHelper.java:84)
	at org.testng.internal.Invoker.invokeMethod(Invoker.java:714)
	at org.testng.internal.Invoker.invokeTestMethod(Invoker.java:901)
	at org.testng.internal.Invoker.invokeTestMethods(Invoker.java:1231)
	at org.testng.internal.TestMethodWorker.invokeTestMethods(TestMethodWorker.java:127)
	at org.testng.internal.TestMethodWorker.run(TestMethodWorker.java:111)
	at org.testng.TestRunner.privateRun(TestRunner.java:767)
	at org.testng.TestRunner.run(TestRunner.java:617)
	at org.testng.SuiteRunner.runTest(SuiteRunner.java:334)
	at org.testng.SuiteRunner.runSequentially(SuiteRunner.java:329)
	at org.testng.SuiteRunner.privateRun(SuiteRunner.java:291)
	at org.testng.SuiteRunner.run(SuiteRunner.java:240)
	at org.testng.SuiteRunnerWorker.runSuite(SuiteRunnerWorker.java:52)
	at org.testng.SuiteRunnerWorker.run(SuiteRunnerWorker.java:86)
	at org.testng.TestNG.runSuitesSequentially(TestNG.java:1224)
	at org.testng.TestNG.runSuitesLocally(TestNG.java:1149)
	at org.testng.TestNG.run(TestNG.java:1057)
	at org.testng.remote.RemoteTestNG.run(RemoteTestNG.java:111)
	at org.testng.remote.RemoteTestNG.initAndRun(RemoteTestNG.java:204)
	at org.testng.remote.RemoteTestNG.main(RemoteTestNG.java:175)
Caused by: java.lang.OutOfMemoryError: Java heap space
	at com.mysql.jdbc.MysqlIO.nextRowFast(MysqlIO.java:1676)
	at com.mysql.jdbc.MysqlIO.nextRow(MysqlIO.java:1434)
	at com.mysql.jdbc.MysqlIO.readSingleRowSet(MysqlIO.java:2936)
	at com.mysql.jdbc.MysqlIO.getResultSet(MysqlIO.java:477)
	at com.mysql.jdbc.MysqlIO.readResultsForQueryOrUpdate(MysqlIO.java:2631)
	at com.mysql.jdbc.MysqlIO.readAllResults(MysqlIO.java:1800)
	at com.mysql.jdbc.MysqlIO.sqlQueryDirect(MysqlIO.java:2221)
	at com.mysql.jdbc.ConnectionImpl.execSQL(ConnectionImpl.java:2618)
	at com.mysql.jdbc.ConnectionImpl.execSQL(ConnectionImpl.java:2568)
	at com.mysql.jdbc.StatementImpl.executeQuery(StatementImpl.java:1557)
	at com.sapphire.etl.Demo.demoCaseSeriousness(Demo.java:326)
	at sun.reflect.NativeMethodAccessorImpl.invoke0(Native Method)
	at sun.reflect.NativeMethodAccessorImpl.invoke(NativeMethodAccessorImpl.java:39)
	at sun.reflect.DelegatingMethodAccessorImpl.invoke(DelegatingMethodAccessorImpl.java:25)
	at java.lang.reflect.Method.invoke(Method.java:597)
	at org.testng.internal.MethodInvocationHelper.invokeMethod(MethodInvocationHelper.java:84)
	at org.testng.internal.Invoker.invokeMethod(Invoker.java:714)
	at org.testng.internal.Invoker.invokeTestMethod(Invoker.java:901)
	at org.testng.internal.Invoker.invokeTestMethods(Invoker.java:1231)
	at org.testng.internal.TestMethodWorker.invokeTestMethods(TestMethodWorker.java:127)
	at org.testng.internal.TestMethodWorker.run(TestMethodWorker.java:111)
	at org.testng.TestRunner.privateRun(TestRunner.java:767)
	at org.testng.TestRunner.run(TestRunner.java:617)
	at org.testng.SuiteRunner.runTest(SuiteRunner.java:334)
	at org.testng.SuiteRunner.runSequentially(SuiteRunner.java:329)
	at org.testng.SuiteRunner.privateRun(SuiteRunner.java:291)
	at org.testng.SuiteRunner.run(SuiteRunner.java:240)
	at org.testng.SuiteRunnerWorker.runSuite(SuiteRunnerWorker.java:52)
	at org.testng.SuiteRunnerWorker.run(SuiteRunnerWorker.java:86)
	at org.testng.TestNG.runSuitesSequentially(TestNG.java:1224)
	at org.testng.TestNG.runSuitesLocally(TestNG.java:1149)
	at org.testng.TestNG.run(TestNG.java:1057)
]]>
    </error>
  </testcase> <!-- demoCaseSeriousness -->
  <testcase name="demoCASE_ID" time="0.233" classname="com.sapphire.etl.Demo"/>
  <testcase name="demoCaseGenderDEC" time="0.026" classname="com.sapphire.etl.Demo"/>
  <testcase name="demoCaseValidTo" time="0.030" classname="com.sapphire.etl.Demo">
    <error type="java.lang.AssertionError" message="ERROR">
      <![CDATA[java.lang.AssertionError: ERROR
	at org.testng.Assert.fail(Assert.java:83)
	at com.sapphire.etl.Demo.demoCaseValidTo(Demo.java:85)
	at sun.reflect.NativeMethodAccessorImpl.invoke0(Native Method)
	at sun.reflect.NativeMethodAccessorImpl.invoke(NativeMethodAccessorImpl.java:39)
	at sun.reflect.DelegatingMethodAccessorImpl.invoke(DelegatingMethodAccessorImpl.java:25)
	at java.lang.reflect.Method.invoke(Method.java:597)
	at org.testng.internal.MethodInvocationHelper.invokeMethod(MethodInvocationHelper.java:84)
	at org.testng.internal.Invoker.invokeMethod(Invoker.java:714)
	at org.testng.internal.Invoker.invokeTestMethod(Invoker.java:901)
	at org.testng.internal.Invoker.invokeTestMethods(Invoker.java:1231)
	at org.testng.internal.TestMethodWorker.invokeTestMethods(TestMethodWorker.java:127)
	at org.testng.internal.TestMethodWorker.run(TestMethodWorker.java:111)
	at org.testng.TestRunner.privateRun(TestRunner.java:767)
	at org.testng.TestRunner.run(TestRunner.java:617)
	at org.testng.SuiteRunner.runTest(SuiteRunner.java:334)
	at org.testng.SuiteRunner.runSequentially(SuiteRunner.java:329)
	at org.testng.SuiteRunner.privateRun(SuiteRunner.java:291)
	at org.testng.SuiteRunner.run(SuiteRunner.java:240)
	at org.testng.SuiteRunnerWorker.runSuite(SuiteRunnerWorker.java:52)
	at org.testng.SuiteRunnerWorker.run(SuiteRunnerWorker.java:86)
	at org.testng.TestNG.runSuitesSequentially(TestNG.java:1224)
	at org.testng.TestNG.runSuitesLocally(TestNG.java:1149)
	at org.testng.TestNG.run(TestNG.java:1057)
	at org.testng.remote.RemoteTestNG.run(RemoteTestNG.java:111)
	at org.testng.remote.RemoteTestNG.initAndRun(RemoteTestNG.java:204)
	at org.testng.remote.RemoteTestNG.main(RemoteTestNG.java:175)
Caused by: java.lang.AssertionError: Is null expected [null] but found [2707317]
	at org.testng.Assert.fail(Assert.java:94)
	at org.testng.Assert.failNotSame(Assert.java:490)
	at org.testng.Assert.assertNull(Assert.java:426)
	at com.sapphire.etl.Demo.demoCaseValidTo(Demo.java:79)
	... 24 more
]]>
    </error>
  </testcase> <!-- demoCaseValidTo -->
  <testcase name="demoCaseValiFrom" time="0.030" classname="com.sapphire.etl.Demo"/>
  <testcase name="demoISR_ID" time="0.031" classname="com.sapphire.etl.Demo"/>
</testsuite> <!-- com.sapphire.etl.Demo -->
