<?xml version="1.0" encoding="UTF-8"?>
<!-- Generated by org.testng.reporters.JUnitReportReporter -->
<testsuite hostname="PDWIVEDI" name="com.sapphire.etl.CaseCountInQtr" tests="2" failures="0" timestamp="28 May 2014 13:35:03 GMT" time="1.764" errors="1">
  <testcase name="AERSCaseCountDemo" time="1.491" classname="com.sapphire.etl.CaseCountInQtr">
    <error type="java.lang.AssertionError" message="SELECT fda_rel_qtr,count(*) FROM aers.aers_demo group by fda_rel_qtr">
      <![CDATA[java.lang.AssertionError: SELECT fda_rel_qtr,count(*) FROM aers.aers_demo group by fda_rel_qtr
	at org.testng.Assert.fail(Assert.java:83)
	at com.sapphire.etl.CaseCountInQtr.AERSCaseCountDemo(CaseCountInQtr.java:74)
	at sun.reflect.NativeMethodAccessorImpl.invoke0(Native Method)
	at sun.reflect.NativeMethodAccessorImpl.invoke(NativeMethodAccessorImpl.java:39)
	at sun.reflect.DelegatingMethodAccessorImpl.invoke(DelegatingMethodAccessorImpl.java:25)
	at java.lang.reflect.Method.invoke(Method.java:597)
	at org.testng.internal.MethodInvocationHelper.invokeMethod(MethodInvocationHelper.java:84)
	at org.testng.internal.Invoker.invokeMethod(Invoker.java:714)
	at org.testng.internal.Invoker.invokeTestMethod(Invoker.java:901)
	at org.testng.internal.Invoker.invokeTestMethods(Invoker.java:1231)
	at org.testng.internal.TestMethodWorker.invokeTestMethods(TestMethodWorker.java:127)
	at org.testng.internal.TestMethodWorker.run(TestMethodWorker.java:111)
	at org.testng.TestRunner.privateRun(TestRunner.java:767)
	at org.testng.TestRunner.run(TestRunner.java:617)
	at org.testng.SuiteRunner.runTest(SuiteRunner.java:334)
	at org.testng.SuiteRunner.runSequentially(SuiteRunner.java:329)
	at org.testng.SuiteRunner.privateRun(SuiteRunner.java:291)
	at org.testng.SuiteRunner.run(SuiteRunner.java:240)
	at org.testng.SuiteRunnerWorker.runSuite(SuiteRunnerWorker.java:52)
	at org.testng.SuiteRunnerWorker.run(SuiteRunnerWorker.java:86)
	at org.testng.TestNG.runSuitesSequentially(TestNG.java:1224)
	at org.testng.TestNG.runSuitesLocally(TestNG.java:1149)
	at org.testng.TestNG.run(TestNG.java:1057)
	at org.testng.remote.RemoteTestNG.run(RemoteTestNG.java:111)
	at org.testng.remote.RemoteTestNG.initAndRun(RemoteTestNG.java:204)
	at org.testng.remote.RemoteTestNG.main(RemoteTestNG.java:175)
Caused by: java.lang.AssertionError: null: lists don't have the same size expected [132] but found [130]
	at org.testng.Assert.fail(Assert.java:94)
	at org.testng.Assert.failNotEquals(Assert.java:494)
	at org.testng.Assert.assertEquals(Assert.java:123)
	at org.testng.Assert.assertEquals(Assert.java:370)
	at org.testng.Assert.assertEquals(Assert.java:537)
	at org.testng.Assert.assertEquals(Assert.java:514)
	at com.sapphire.etl.CaseCountInQtr.AERSCaseCountDemo(CaseCountInQtr.java:71)
	... 24 more
]]>
    </error>
  </testcase> <!-- AERSCaseCountDemo -->
  <testcase name="AERSCaseCounts" time="0.273" classname="com.sapphire.etl.CaseCountInQtr"/>
</testsuite> <!-- com.sapphire.etl.CaseCountInQtr -->
