<?xml version="1.0" encoding="UTF-8"?>
<!-- Generated by org.testng.reporters.JUnitReportReporter -->
<testsuite hostname="PDWIVEDI" name="com.sapphire.etl.DemoCaseValidity" tests="2" failures="0" timestamp="26 May 2014 09:28:25 GMT" time="0.292" errors="1">
  <testcase name="demoCaseValiFrom" time="0.196" classname="com.sapphire.etl.DemoCaseValidity"/>
  <testcase name="demoCaseValiTo" time="0.096" classname="com.sapphire.etl.DemoCaseValidity">
    <error type="java.lang.AssertionError" message="ERROR">
      <![CDATA[java.lang.AssertionError: ERROR
	at org.testng.Assert.fail(Assert.java:83)
	at com.sapphire.etl.DemoCaseValidity.demoCaseValiTo(DemoCaseValidity.java:89)
	at sun.reflect.NativeMethodAccessorImpl.invoke0(Native Method)
	at sun.reflect.NativeMethodAccessorImpl.invoke(NativeMethodAccessorImpl.java:39)
	at sun.reflect.DelegatingMethodAccessorImpl.invoke(DelegatingMethodAccessorImpl.java:25)
	at java.lang.reflect.Method.invoke(Method.java:597)
	at org.testng.internal.MethodInvocationHelper.invokeMethod(MethodInvocationHelper.java:84)
	at org.testng.internal.Invoker.invokeMethod(Invoker.java:714)
	at org.testng.internal.Invoker.invokeTestMethod(Invoker.java:901)
	at org.testng.internal.Invoker.invokeTestMethods(Invoker.java:1231)
	at org.testng.internal.TestMethodWorker.invokeTestMethods(TestMethodWorker.java:127)
	at org.testng.internal.TestMethodWorker.run(TestMethodWorker.java:111)
	at org.testng.TestRunner.privateRun(TestRunner.java:767)
	at org.testng.TestRunner.run(TestRunner.java:617)
	at org.testng.SuiteRunner.runTest(SuiteRunner.java:334)
	at org.testng.SuiteRunner.runSequentially(SuiteRunner.java:329)
	at org.testng.SuiteRunner.privateRun(SuiteRunner.java:291)
	at org.testng.SuiteRunner.run(SuiteRunner.java:240)
	at org.testng.SuiteRunnerWorker.runSuite(SuiteRunnerWorker.java:52)
	at org.testng.SuiteRunnerWorker.run(SuiteRunnerWorker.java:86)
	at org.testng.TestNG.runSuitesSequentially(TestNG.java:1224)
	at org.testng.TestNG.runSuitesLocally(TestNG.java:1149)
	at org.testng.TestNG.run(TestNG.java:1057)
	at org.testng.remote.RemoteTestNG.run(RemoteTestNG.java:111)
	at org.testng.remote.RemoteTestNG.initAndRun(RemoteTestNG.java:204)
	at org.testng.remote.RemoteTestNG.main(RemoteTestNG.java:175)
Caused by: java.lang.AssertionError: Is null expected [null] but found [2707317]
	at org.testng.Assert.fail(Assert.java:94)
	at org.testng.Assert.failNotSame(Assert.java:490)
	at org.testng.Assert.assertNull(Assert.java:426)
	at com.sapphire.etl.DemoCaseValidity.demoCaseValiTo(DemoCaseValidity.java:83)
	... 24 more
]]>
    </error>
  </testcase> <!-- demoCaseValiTo -->
</testsuite> <!-- com.sapphire.etl.DemoCaseValidity -->
